Workbook

Sheet Australia
A1: Impact_ID | B1: Impacts | C1: Pressures_Name | D1: Pressure_ID | E1: Pressures | F1: Impact_Pressure | G1: IP_UID | H1: IP_ID | I1: ID_Colour | J1: R | K1: G | L1: B | M1: A | N1: Code | O1: Impact_Descriptor | P1: Pressure_Descriptor | Q1: TimeO_Ev | R1: TimeL_Ev | S1: TimeM_Ev | T1: TimeD_Ev | U1: Space_Ev | V1: ModA | W1: ModB | X1: ModC | Y1: ModD | Z1: ModE | AA1: ModF | AB1: ModG | AC1: ModH | AD1: ModI | AE1: ConA | AF1: ConB | AG1: ConC | AH1: ConD | AI1: ConE | AJ1: ConF | AK1: ConG | AL1: ConH | AM1: ConI | AN1: ConJ | AO1: ConK | AP1: ConL | AQ1: ConM | AR1: ConN | AS1: ConO | AT1: ConP | AU1: LfA | AV1: LfB | AW1: Biomass_Ev | AX1: Water_persistence_Ev | AY1: CanopyC_Ev | AZ1: FireScar_ImpactEvidence | BA1: Hydroperiod_ImpactEvidence | BB1: HighTemp_ImpactEvidence | BD1: CTVc | BE1: NTVc | BF1: CAVc | BG1: NAVc | BH1: ASc | BI1: BSc | BJ1: AWc | BK1: NWc | BL1: Wc | BM1: CTVc2 | BN1: NTVc2 | BO1: CAV2 | BP1: NAVc2 | BQ1: ASc2 | BR1: BSc2 | BS1: AWc2 | BT1: NWc2 | BU1: Wc2 | BV1: Lifeform | BW1: canopycover | BX1: CANOPY HEIGHT (m) | BY1: SPATIAL DISTRIBUTION | BZ1: LfC | CA1: LfD | CB1: CovA | CC1: CovB | CD1: CovC | CE1: CovD | CF1: CovE | CG1: CovF | CH1: CovG | CI1: CovH | CJ1: CovI | CK1: CovJ | CL1: CovK | CM1: CovL | CN1: CovM | CO1: CovN | CP1: CovO | CQ1: CovP | CR1: CovQ | CS1: CovR | CT1: CovS | CU1: CovT | CV1: CovU | CW1: CovV | CX1: CovW | CY1: CovX | CZ1: Wstate | DA1: WperA | DB1: WperB | DC1: WperC | DD1: WperD | DE1: WperE | DF1: WperF | DG1: WseaA | DH1: WseaB | DI1: WseaC | DJ1: WseaD | DK1: AGB_Ev | DL1: AGBSD_Ev | DM1: IntEl_Ev | DN1: Canopycoa_Ev | DO1: ActiveFire | DP1: Burnscar | DQ1: Smoke | DR1: Turbidity | DS1: Flooding | DT1: Hydrograph | DU1: SnowExtent | DV1: Sediment | DW1: OceanAcidity | DX1: SeaSurfTemp | DY1: LandSurfTemp | DZ1: AtmosTemp | EA1: AtmosPress | EB1: Precipitation | EC1: Windspeed | ED1: LightningStrikesData | EE1: SeaSurfaceHeight | EF1: SeismicRecords | EG1: DogitalSurfaceModel | EH1: ForestInventory | EI1: WildlifeCensus | EJ1: StockRecords | EK1: ExtractionRegister | EL1: PlanningData | EM1: AgriRecords | EN1: AgrichemRecords | EO1: Pathogens | EP1: SoilQual | EQ1: TrafficData | ER1: WaterQual | ES1: WaterUsage | ET1: Check
A2: 1 | B2: Accretion | C2: sediment transport | D2: 111 | E2: Sediment transport | F2: Accretion (sediment transport) | G2: 1 | H2: =(A2*1000)+D2 -> 1111 | I2: Medium Slate Blue | J2: 205 | K2: 133 | L2: 63 | M2: 255 | N2: =G2&": ("&J2&", "&K2&", "&L2&", "&M2&", "&F2&": "&H2&")," -> 1: (205, 133, 63, 255, Accretion (sediment transport): 1111), | O2: =VLOOKUP(Australia!B2,Impacts!$A$2:$B$80,2, FALSE) -> The build-up of sediments to form land or shoaling in coastal waters or waterways. | P2: =VLOOKUP(E2,Pressures!$A$2:$B$145,2,FALSE) -> The movement of solid particles (sediment) caused by movement of the water volume within which they are contained and the force of gravity. | AA2: 216216 | AD2: 220220 | AW2: 0 | AX2: 0 | AZ2: 1 | BA2: 2 | BB2: 3 | BH2: 216216 | CZ2: 11 | DV2: 1 | ET2: =SUM(DO2:ES2) -> 1
A3: 2 | B3: Algal bloom | C3: eutrophication | D3: 36 | E3: Eutrophication | F3: Algal bloom (eutrophication) | G3: 2 | H3: =(A3*1000)+D3 -> 2036 | I3: Light Slate Gray | J3: 0 | K3: 255 | L3: 0 | M3: 255 | N3: =G3&": ("&J3&", "&K3&", "&L3&", "&M3&", "&F3&": "&H3&")," -> 2: (0, 255, 0, 255, Algal bloom (eutrophication): 2036), | O3: =VLOOKUP(Australia!B3,Impacts!$A$2:$B$80,2, FALSE) -> A sudden proliferation of algae (microscopic plants) that occurs near the surface of a body of water. | P3: =VLOOKUP(E3,Pressures!$A$2:$B$145,2,FALSE) -> A natural process that results from accumulation of nutrients in lakes or other bodies of water. | AB3: 227227 | AC3: 228228 | AD3: 220220 | AW3: 0 | AX3: 0 | AZ3: 1 | BA3: 2 | BB3: 3 | CZ3: 11 | ER3: 1 | ET3: =SUM(DO3:ES3) -> 1
A4: 2 | B4: Algal bloom | C4: high inland water temperatures | D4: 57 | E4: High inland water temperatures | F4: Algal bloom (high inland water temperatures) | G4: 3 | H4: =(A4*1000)+D4 -> 2057 | I4: Medium Orchid | J4: 173 | K4: 255 | L4: 47 | M4: 255 | N4: =G4&": ("&J4&", "&K4&", "&L4&", "&M4&", "&F4&": "&H4&")," -> 3: (173, 255, 47, 255, Algal bloom (high inland water temperatures): 2057), | O4: =VLOOKUP(Australia!B4,Impacts!$A$2:$B$80,2, FALSE) -> A sudden proliferation of algae (microscopic plants) that occurs near the surface of a body of water. | P4: =VLOOKUP(E4,Pressures!$A$2:$B$145,2,FALSE) -> Water temperatures of rivers, lakes, floodplains, reservoirs, wetlands, and inland saline systems that are warmer than usual. | AB4: 227227 | AC4: 228228 | AD4: 220220 | AW4: 0 | AX4: 0 | AZ4: 1 | BA4: 2 | BB4: 3 | CZ4: 11 | DY4: 1 | ET4: =SUM(DO4:ES4) -> 1
A5: 2 | B5: Algal bloom | C5: increased temperature | D5: 64 | E5: Increased temperature | F5: Algal bloom (increased temperature) | G5: 4 | H5: =(A5*1000)+D5 -> 2064 | I5: Light Salmon | J5: 124 | K5: 252 | L5: 0 | M5: 255 | N5: =G5&": ("&J5&", "&K5&", "&L5&", "&M5&", "&F5&": "&H5&")," -> 4: (124, 252, 0, 255, Algal bloom (increased temperature): 2064), | O5: =VLOOKUP(Australia!B5,Impacts!$A$2:$B$80,2, FALSE) -> A sudden proliferation of algae (microscopic plants) that occurs near the surface of a body of water. | P5: =VLOOKUP(E5,Pressures!$A$2:$B$145,2,FALSE) -> Increased amount of heat in a place. | AB5: 227227 | AC5: 228228 | AD5: 220220 | AW5: 0 | AX5: 0 | AZ5: 1 | BA5: 2 | BB5: 3 | CZ5: 11 | DZ5: 1 | ET5: =SUM(DO5:ES5) -> 1
A6: 3 | B6: Algal dieback | C6: decreased temperature | D6: 26 | E6: Decreased temperature | F6: Algal dieback (decreased temperature) | G6: 5 | H6: =(A6*1000)+D6 -> 3026 | I6: Dark Turquoise | J6: 210 | K6: 105 | L6: 30 | M6: 255 | N6: =G6&": ("&J6&", "&K6&", "&L6&", "&M6&", "&F6&": "&H6&")," -> 5: (210, 105, 30, 255, Algal dieback (decreased temperature): 3026), | O6: =VLOOKUP(Australia!B6,Impacts!$A$2:$B$80,2, FALSE) -> Loss of algae (microscopic plants) that occurs near the surface of a body of water. | P6: =VLOOKUP(E6,Pressures!$A$2:$B$145,2,FALSE) -> Decreased amount of heat in a place. | AB6: 227227 | AC6: 228228 | AD6: 220220 | AW6: 0 | AX6: 0 | AZ6: 1 | BA6: 2 | BB6: 3 | BD6: 111111 | BE6: 112112 | BV6: 22 | BX6: -□ | BY6: - | CZ6: 11 | DY6: 1 | DZ6: 1 | ET6: =SUM(DO6:ES6) -> 2
A7: 4 | B7: Bare soil exposure | C7: burning | D7: 11 | E7: Burning | F7: Bare soil exposure (burning) | G7: 6 | H7: =(A7*1000)+D7 -> 4011 | I7: Light Sky Blue | J7: 119 | K7: 63 | L7: 26 | M7: 255 | N7: =G7&": ("&J7&", "&K7&", "&L7&", "&M7&", "&F7&": "&H7&")," -> 6: (119, 63, 26, 255, Bare soil exposure (burning): 4011), | O7: =VLOOKUP(Australia!B7,Impacts!$A$2:$B$80,2, FALSE) -> Appearance of underlying soil following human or natural disturbance.. | P7: =VLOOKUP(E7,Pressures!$A$2:$B$145,2,FALSE) -> On fire. | AE7: 111216 | AF7: 112216 | AG7: 123216 | AH7: 124216 | AW7: 0 | AX7: 0 | AZ7: 1 | BA7: 2 | BB7: 3 | BD7: 111111 | BE7: 112112 | BV7: 11 | BX7: -□ | BY7: - | DO7: 1 | DP7: 1 | DQ7: 1 | ET7: =SUM(DO7:ES7) -> 3
A8: 4 | B8: Bare soil exposure | C8: erosion | D8: 35 | E8: Erosion | F8: Bare soil exposure (erosion) | G8: 7 | H8: =(A8*1000)+D8 -> 4035 | I8: Light Steel Blue | J8: 244 | K8: 164 | L8: 96 | M8: 255 | N8: =G8&": ("&J8&", "&K8&", "&L8&", "&M8&", "&F8&": "&H8&")," -> 7: (244, 164, 96, 255, Bare soil exposure (erosion): 4035), | O8: =VLOOKUP(Australia!B8,Impacts!$A$2:$B$80,2, FALSE) -> Appearance of underlying soil following human or natural disturbance.. | P8: =VLOOKUP(E8,Pressures!$A$2:$B$145,2,FALSE) -> Geological process in which earth materials are worn away and transported by natural forces such as wind or water. | AE8: 111216 | AF8: 112216 | AG8: 123216 | AH8: 124216 | AW8: 0 | AX8: 0 | AZ8: 1 | BA8: 2 | BB8: 3 | BD8: 111111 | BE8: 112112 | BV8: 11 | BX8: -□ | BY8: - | DS8: 1 | EC8: 1 | ET8: =SUM(DO8:ES8) -> 2
A9: 4 | B9: Bare soil exposure | C9: ploughing | D9: 91 | E9: Ploughing | F9: Bare soil exposure (ploughing) | G9: 8 | H9: =(A9*1000)+D9 -> 4091 | I9: Medium Purple | J9: 184 | K9: 134 | L9: 11 | M9: 255 | N9: =G9&": ("&J9&", "&K9&", "&L9&", "&M9&", "&F9&": "&H9&")," -> 8: (184, 134, 11, 255, Bare soil exposure (ploughing): 4091), | O9: =VLOOKUP(Australia!B9,Impacts!$A$2:$B$80,2, FALSE) -> Appearance of underlying soil following human or natural disturbance.. | P9: =VLOOKUP(E9,Pressures!$A$2:$B$145,2,FALSE) -> Making furrows in land mechanically, by breaking and turning over the soil. | AE9: 111216 | AW9: 0 | AX9: 0 | AZ9: 1 | BA9: 2 | BB9: 3 | BL9: 220220 | EM9: 1 | ET9: =SUM(DO9:ES9) -> 1
A10: 4 | B10: Bare soil exposure | C10: tillage | D10: 126 | E10: Tillage | F10: Bare soil exposure (tillage) | G10: 9 | H10: =(A10*1000)+D10 -> 4126 | I10: Pale Violet Red | J10: 169 | K10: 169 | L10: 169 | M10: 255 | N10: =G10&": ("&J10&", "&K10&", "&L10&", "&M10&", "&F10&": "&H10&")," -> 9: (169, 169, 169, 255, Bare soil exposure (tillage): 4126), | O10: =VLOOKUP(Australia!B10,Impacts!$A$2:$B$80,2, FALSE) -> Appearance of underlying soil following human or natural disturbance.. | P10: =VLOOKUP(E10,Pressures!$A$2:$B$145,2,FALSE) -> Preparation of soil for agricultural use through mechanical intervention such as digging, stirring, and overturning. | AE10: 111216 | AW10: 0 | AX10: 0 | AZ10: 1 | BA10: 2 | BB10: 3 | BL10: 220220 | EM10: 1 | ET10: =SUM(DO10:ES10) -> 1
A11: 5 | B11: Blackwater event | C11: inundation following extended drought | D11: 69 | E11: Inundation following extended drought | F11: Blackwater event (inundation following extended drought) | G11: 10 | H11: =(A11*1000)+D11 -> 5069 | I11: Light Green | J11: 61 | K11: 7 | L11: 52 | M11: 255 | N11: =G11&": ("&J11&", "&K11&", "&L11&", "&M11&", "&F11&": "&H11&")," -> 10: (61, 7, 52, 255, Blackwater event (inundation following extended drought): 5069), | O11: =VLOOKUP(Australia!B11,Impacts!$A$2:$B$80,2, FALSE) -> When organic material is inundated or washed into waterways and consumed by bacteria. | P11: =VLOOKUP(E11,Pressures!$A$2:$B$145,2,FALSE) -> Progressive submergence of land or structures through flooding and following an extended period of drought. | AB11: 227227 | AC11: 228228 | AD11: 220220 | AW11: 0 | AX11: 0 | AZ11: 1 | BA11: 2 | BB11: 3 | BL11: 220220 | CZ11: 11 | DS11: 1 | EB11: 1 | ET11: =SUM(DO11:ES11) -> 2
A12: 6 | B12: Browning (vegetation) | C12: decreased precipitation | D12: 25 | E12: Decreased precipitation | F12: Browning (vegetation) (decreased precipitation) | G12: 11 | H12: =(A12*1000)+D12 -> 6025 | I12: Medium Spring Green | J12: 255 | K12: 228 | L12: 181 | M12: 255 | N12: =G12&": ("&J12&", "&K12&", "&L12&", "&M12&", "&F12&": "&H12&")," -> 11: (255, 228, 181, 255, Browning (vegetation) (decreased precipitation): 6025), | O12: =VLOOKUP(Australia!B12,Impacts!$A$2:$B$80,2, FALSE) -> A decrease in the amount or loss of photosynthetically active pigments in vegetation. | P12: =VLOOKUP(E12,Pressures!$A$2:$B$145,2,FALSE) -> Decreased condensation of water vapour in the atmosphere forming rain, snow, sleet or dew. | V12: 111111 | W12: 112112 | X12: 123123 | Y12: 124124 | CB12: 1012 | CC12: 1013 | CD12: 1015 | CE12: 1016 | CF12: 1213 | CG12: 1215 | CH12: 1216 | CI12: 1315 | CJ12: 1316 | CK12: 1516 | EB12: 1 | ET12: =SUM(DO12:ES12) -> 1
A13: 7 | B13: Building or infrastucture abandonment | C13: dam removal | D13: 21 | E13: Dam removal | F13: Building or infrastructure abandonment (dam removal) | G13: 12 | H13: =(A13*1000)+D13 -> 7021 | I13: Light Cyan | J13: 147 | K13: 112 | L13: 219 | M13: 255 | N13: =G13&": ("&J13&", "&K13&", "&L13&", "&M13&", "&F13&": "&H13&")," -> 12: (147, 112, 219, 255, Building or infrastructure abandonment (dam removal): 7021), | O13: =VLOOKUP(Australia!B13,Impacts!$A$2:$B$80,2, FALSE) -> Buildings dehabited or no longer in use. | P13: =VLOOKUP(E13,Pressures!$A$2:$B$145,2,FALSE) -> Demolition/decommissioning of a dam enabling reinstatement of unconstrained water flow and typically reducing pooled water. | AE13: 215216 | AF13: 227216 | AG13: 220216 | AW13: 0 | AX13: 0 | AZ13: 1 | BA13: 2 | BB13: 3 | BL13: 220220 | ES13: 1 | ET13: =SUM(DO13:ES13) -> 1
A14: 7 | B14: Building or infrastucture abandonment | C14: flooding | D14: 44 | E14: Flooding | F14: Building or infrastructure abandonment (flooding) | G14: 13 | H14: =(A14*1000)+D14 -> 7044 | I14: Dark Orchid | J14: 123 | K14: 104 | L14: 238 | M14: 255 | N14: =G14&": ("&J14&", "&K14&", "&L14&", "&M14&", "&F14&": "&H14&")," -> 13: (123, 104, 238, 255, Building or infrastructure abandonment (flooding): 7044), | O14: =VLOOKUP(Australia!B14,Impacts!$A$2:$B$80,2, FALSE) -> Buildings dehabited or no longer in use. | P14: =VLOOKUP(E14,Pressures!$A$2:$B$145,2,FALSE) -> The inundation of water over land that is generally dry. | AE14: 215220 | AF14: 215227 | AG14: 215220 | AW14: 0 | AX14: 0 | AZ14: 1 | BA14: 2 | BB14: 3 | DS14: 1 | ET14: =SUM(DO14:ES14) -> 1
A15: 7 | B15: Building or infrastucture abandonment | C15: increased wind | D15: 66 | E15: Increased wind | F15: Building or infrastructure abandonment (increased wind) | G15: 14 | H15: =(A15*1000)+D15 -> 7066 | I15: Cornflower Blue | J15: 70 | K15: 130 | L15: 180 | M15: 255 | N15: =G15&": ("&J15&", "&K15&", "&L15&", "&M15&", "&F15&": "&H15&")," -> 14: (70, 130, 180, 255, Building or infrastructure abandonment (increased wind): 7066), | O15: =VLOOKUP(Australia!B15,Impacts!$A$2:$B$80,2, FALSE) -> Buildings dehabited or no longer in use. | P15: =VLOOKUP(E15,Pressures!$A$2:$B$145,2,FALSE) -> A higher velocity of air movement into an area associated with, for example, cyclones, hurricans, typhoons, tornados, thunderstorms, storms or ice storms. | Z15: 215215 | AW15: 0 | AX15: 0 | AZ15: 1 | BA15: 2 | BB15: 3 | BL15: 220220 | EC15: 1 | ET15: =SUM(DO15:ES15) -> 1
A16: 7 | B16: Building or infrastucture abandonment | C16: urban fire | D16: 131 | E16: Urban fire | F16: Building or infrastructure abandonment (urban fire) | G16: 15 | H16: =(A16*1000)+D16 -> 7131 | I16: Light Yellow | J16: 148 | K16: 0 | L16: 211 | M16: 255 | N16: =G16&": ("&J16&", "&K16&", "&L16&", "&M16&", "&F16&": "&H16&")," -> 15: (148, 0, 211, 255, Building or infrastructure abandonment (urban fire): 7131), | O16: =VLOOKUP(Australia!B16,Impacts!$A$2:$B$80,2, FALSE) -> Buildings dehabited or no longer in use. | P16: =VLOOKUP(E16,Pressures!$A$2:$B$145,2,FALSE) -> Urban fire occurs primarily in cities or towns with the potential to rapidly spread to adjoining structures. | Z16: 215215 | AE16: 215216 | AW16: 0 | AX16: 0 | AZ16: 1 | BA16: 2 | BB16: 3 | BL16: 220220 | DO16: 1 | DP16: 1 | DQ16: 1 | ET16: =SUM(DO16:ES16) -> 3
A17: 8 | B17: Compaction | C17: increased traffic | D17: 65 | E17: Increased traffic | F17: Compaction (increased traffic) | G17: 16 | H17: =(A17*1000)+D17 -> 8065 | I17: Dark Orange | J17: 218 | K17: 165 | L17: 32 | M17: 255 | N17: =G17&": ("&J17&", "&K17&", "&L17&", "&M17&", "&F17&": "&H17&")," -> 16: (218, 165, 32, 255, Compaction (increased traffic): 8065), | O17: =VLOOKUP(Australia!B17,Impacts!$A$2:$B$80,2, FALSE) -> Process that brings about an increase in soil density or unit weight. | P17: =VLOOKUP(E17,Pressures!$A$2:$B$145,2,FALSE) -> A greater number of vehicles moving along roads, or the amount of aircraft, trains, or ships moving along a route. | AA17: 216216 | AW17: 0 | AX17: 0 | AZ17: 1 | BA17: 2 | BB17: 3 | BD17: 111111 | BF17: 123123 | EQ17: 1 | ET17: =SUM(DO17:ES17) -> 1
A18: 8 | B18: Compaction | C18: overgrazing (natural) | D18: 86 | E18: Overgrazing (natural) | F18: Compaction (overgrazing (natural)) | G18: 17 | H18: =(A18*1000)+D18 -> 8086 | I18: Pale Green | J18: 240 | K18: 230 | L18: 140 | M18: 255 | N18: =G18&": ("&J18&", "&K18&", "&L18&", "&M18&", "&F18&": "&H18&")," -> 17: (240, 230, 140, 255, Compaction (overgrazing (natural)): 8086), | O18: =VLOOKUP(Australia!B18,Impacts!$A$2:$B$80,2, FALSE) -> Process that brings about an increase in soil density or unit weight. | P18: =VLOOKUP(E18,Pressures!$A$2:$B$145,2,FALSE) -> Excessive grazing by natural animal populations without sufficient rest, resulting in declines in the biomass or health of vegetation. | AA18: 216216 | AW18: -1 | AX18: 0 | AZ18: 1 | BA18: 2 | BB18: 3 | BD18: 111111 | EI18: 1 | ET18: =SUM(DO18:ES18) -> 1
A19: 8 | B19: Compaction | C19: overgrazing (stock) | D19: 87 | E19: Overgrazing (stock) | F19: Compaction (overgrazing (stock)) | G19: 18 | H19: =(A19*1000)+D19 -> 8087 | I19: Medium Aquamarine | J19: 222 | K19: 184 | L19: 135 | M19: 255 | N19: =G19&": ("&J19&", "&K19&", "&L19&", "&M19&", "&F19&": "&H19&")," -> 18: (222, 184, 135, 255, Compaction (overgrazing (stock)): 8087), | O19: =VLOOKUP(Australia!B19,Impacts!$A$2:$B$80,2, FALSE) -> Process that brings about an increase in soil density or unit weight. | P19: =VLOOKUP(E19,Pressures!$A$2:$B$145,2,FALSE) -> Excessive grazing by domesticated stock without sufficient rest, resulting in declines in the biomass or health of vegetation. | V19: 111111 | W19: 112112 | Y19: 124124 | AW19: -1 | AX19: 0 | AZ19: 1 | BA19: 2 | BB19: 3 | BD19: 111111 | CZ19: 11 | DA19: 11 | EJ19: 1 | ET19: =SUM(DO19:ES19) -> 1
A20: 9 | B20: Coral bleaching | C20: increased acidity | D20: 59 | E20: Increased acidity | F20: Coral bleaching (increased acidity) | G20: 19 | H20: =(A20*1000)+D20 -> 9059 | I20: Light Pink | J20: 250 | K20: 250 | L20: 210 | M20: 255 | N20: =G20&": ("&J20&", "&K20&", "&L20&", "&M20&", "&F20&": "&H20&")," -> 19: (250, 250, 210, 255, Coral bleaching (increased acidity): 9059), | O20: =VLOOKUP(Australia!B20,Impacts!$A$2:$B$80,2, FALSE) -> When the coral host expels its zooxanthellae. | P20: =VLOOKUP(E20,Pressures!$A$2:$B$145,2,FALSE) -> A decrease in the pH of water or soils across the range of alkaline (7-14), neutral (7) to acidic (0 to 7). | AC20: 228228 | AD20: 220220 | AW20: -1 | AX20: 0 | AZ20: 1 | BA20: 2 | BB20: 3 | BD20: 111111 | CZ20: 11 | DA20: 11 | DW20: 1 | ER20: 1 | ET20: =SUM(DO20:ES20) -> 2
A21: 9 | B21: Coral bleaching | C21: prolonged temperature increase | D21: 97 | E21: Prolonged temperature increase | F21: Coral bleaching (prolonged temperature increase) | G21: 20 | H21: =(A21*1000)+D21 -> 9097 | I21: Sea Green | J21: 250 | K21: 240 | L21: 230 | M21: 255 | N21: =G21&": ("&J21&", "&K21&", "&L21&", "&M21&", "&F21&": "&H21&")," -> 20: (250, 240, 230, 255, Coral bleaching (prolonged temperature increase): 9097), | O21: =VLOOKUP(Australia!B21,Impacts!$A$2:$B$80,2, FALSE) -> When the coral host expels its zooxanthellae. | P21: =VLOOKUP(E21,Pressures!$A$2:$B$145,2,FALSE) -> Seasonal to multi-annual increases in temperature compared with past averages. | AC21: 228228 | AD21: 220220 | AW21: -1 | AX21: 0 | AZ21: 1 | BA21: 2 | BB21: 3 | BD21: 111111 | CZ21: 11 | DA21: 11 | DX21: 1 | ET21: =SUM(DO21:ES21) -> 1
A22: 10 | B22: Coral damage | C22: invasive or exotic species | D22: 70 | E22: Invasive/exotic species | F22: Coral damage (invasive or exotic species) | G22: 21 | H22: =(A22*1000)+D22 -> 10070 | I22: Peru | J22: 199 | K22: 21 | L22: 133 | M22: 255 | N22: =G22&": ("&J22&", "&K22&", "&L22&", "&M22&", "&F22&": "&H22&")," -> 21: (199, 21, 133, 255, Coral damage (invasive or exotic species): 10070), | O22: =VLOOKUP(Australia!B22,Impacts!$A$2:$B$80,2, FALSE) -> Physical damage or loss of a coral reef not caused b y changes in water temperature | P22: =VLOOKUP(E22,Pressures!$A$2:$B$145,2,FALSE) -> A plant or animal that has been introduced into a region (terrestrial or aquatic) in which it does not naturally occur. | AC22: 228228 | AD22: 220220 | AW22: -1 | AX22: 0 | AZ22: 1 | BA22: 2 | BB22: 3 | BD22: 111111 | CZ22: 11 | DA22: 11 | EI22: 1 | EO22: 1 | ET22: =SUM(DO22:ES22) -> 2
A23: 10 | B23: Coral damage | C23: pathogens | D23: 88 | E23: Pathogens | F23: Coral damage (pathogens) | G23: 22 | H23: =(A23*1000)+D23 -> 10088 | I23: Indian Red | J23: 255 | K23: 228 | L23: 225 | M23: 255 | N23: =G23&": ("&J23&", "&K23&", "&L23&", "&M23&", "&F23&": "&H23&")," -> 22: (255, 228, 225, 255, Coral damage (pathogens): 10088), | O23: =VLOOKUP(Australia!B23,Impacts!$A$2:$B$80,2, FALSE) -> Physical damage or loss of a coral reef not caused b y changes in water temperature | P23: =VLOOKUP(E23,Pressures!$A$2:$B$145,2,FALSE) -> Any small organism, such as a virus or a bacterium that can cause disease. | AC23: 228228 | AD23: 220220 | AW23: -1 | AX23: 0 | AZ23: 1 | BA23: 2 | BB23: 3 | BD23: 111111 | CZ23: 11 | DA23: 11 | EO23: 1 | ET23: =SUM(DO23:ES23) -> 1
A24: 10 | B24: Coral damage | C24: sedimentation | D24: 112 | E24: Sedimentation | F24: Coral damage (sedimentation) | G24: 23 | H24: =(A24*1000)+D24 -> 10112 | I24: Tan | J24: 255 | K24: 222 | L24: 173 | M24: 255 | N24: =G24&": ("&J24&", "&K24&", "&L24&", "&M24&", "&F24&": "&H24&")," -> 23: (255, 222, 173, 255, Coral damage (sedimentation): 10112), | O24: =VLOOKUP(Australia!B24,Impacts!$A$2:$B$80,2, FALSE) -> Physical damage or loss of a coral reef not caused b y changes in water temperature | P24: =VLOOKUP(E24,Pressures!$A$2:$B$145,2,FALSE) -> Deposition of sediment from flowing water (in channels or floodplains) or standing water (in wetlands, lakes, or oceans). | AC24: 228228 | AD24: 220220 | AW24: -1 | AX24: 0 | AZ24: 1 | BA24: 2 | BB24: 3 | BD24: 111111 | CZ24: 11 | DA24: 11 | DV24: 1 | ET24: =SUM(DO24:ES24) -> 1
A25: 11 | B25: Coral recovery | C25: decreased acidity | D25: 22 | E25: Decreased acidity | F25: Coral recovery (decreased acidity) | G25: 24 | H25: =(A25*1000)+D25 -> 11022 | I25: Dark Khaki | J25: 248 | K25: 131 | L25: 121 | M25: 255 | N25: =G25&": ("&J25&", "&K25&", "&L25&", "&M25&", "&F25&": "&H25&")," -> 24: (248, 131, 121, 255, Coral recovery (decreased acidity): 11022), | O25: =VLOOKUP(Australia!B25,Impacts!$A$2:$B$80,2, FALSE) -> Re-instatement of the previous extent or health of reef-building corals. | P25: =VLOOKUP(E25,Pressures!$A$2:$B$145,2,FALSE) -> A increase in the pH of water or soils across the range of alkaline (7-14), neutral (7) to acidic (0 to 7). | AC25: 228228 | AD25: 220220 | AW25: -1 | AX25: 0 | AZ25: 1 | BA25: 2 | BB25: 3 | BD25: 111111 | CZ25: 11 | DA25: 11 | ER25: 1 | ET25: =SUM(DO25:ES25) -> 1
A26: 11 | B26: Coral recovery | C26: prolonged temperature decrease | D26: 96 | E26: Prolonged temperature decrease | F26: Coral recovery (prolonged temperature decrease) | G26: 25 | H26: =(A26*1000)+D26 -> 11096 | I26: Rosy Brown | J26: 255 | K26: 127 | L26: 80 | M26: 255 | N26: =G26&": ("&J26&", "&K26&", "&L26&", "&M26&", "&F26&": "&H26&")," -> 25: (255, 127, 80, 255, Coral recovery (prolonged temperature decrease): 11096), | O26: =VLOOKUP(Australia!B26,Impacts!$A$2:$B$80,2, FALSE) -> Re-instatement of the previous extent or health of reef-building corals. | P26: =VLOOKUP(E26,Pressures!$A$2:$B$145,2,FALSE) -> Seasonal to multi-annual decreases in temperature compared with past averages. | AC26: 228228 | AD26: 220220 | AW26: -1 | AX26: 0 | AZ26: 1 | BA26: 2 | BB26: 3 | BD26: 111111 | CZ26: 11 | DA26: 11 | DX26: 1 | ET26: =SUM(DO26:ES26) -> 1
A27: 12 | B27: Crop change in cultivated lands | C27: crop rotation | D27: 19 | E27: Crop rotation | F27: Crop change in cultivated lands (crop rotation) | G27: 26 | H27: =(A27*1000)+D27 -> 12019 | I27: Dark Olive Green | J27: 255 | K27: 182 | L27: 30 | M27: 255 | N27: =G27&": ("&J27&", "&K27&", "&L27&", "&M27&", "&F27&": "&H27&")," -> 26: (255, 182, 30, 255, Crop change in cultivated lands (crop rotation): 12019), | O27: =VLOOKUP(Australia!B27,Impacts!$A$2:$B$80,2, FALSE) -> Replacement of one crop type by another. | P27: =VLOOKUP(E27,Pressures!$A$2:$B$145,2,FALSE) -> Alternating between types of crops on a seasonal basis in the same area to limit soil degradation and to help control weeds, diseases and pests. | AU27: 11 | AV27: 22 | AW27: 1 | AX27: 0 | AZ27: 1 | BA27: 2 | BB27: 3 | BJ27: 216111 | BZ27: 12 | CA27: 21 | CB27: 1010 | CC27: 1212 | CD27: 1313 | CE27: 1515 | CF27: 1616 | EM27: 1 | ET27: =SUM(DO27:ES27) -> 1
A28: 13 | B28: Crop damage | C28: drought | D28: 30 | E28: Drought | F28: Crop damage (drought) | G28: 27 | H28: =(A28*1000)+D28 -> 13030 | I28: Olive Drab | J28: 184 | K28: 115 | L28: 51 | M28: 255 | N28: =G28&": ("&J28&", "&K28&", "&L28&", "&M28&", "&F28&": "&H28&")," -> 27: (184, 115, 51, 255, Crop damage (drought): 13030), | O28: =VLOOKUP(Australia!B28,Impacts!$A$2:$B$80,2, FALSE) -> Loss of or harm to crops during or following a disturbance. | P28: =VLOOKUP(E28,Pressures!$A$2:$B$145,2,FALSE) -> Areas considered to be suffering from a serious or severe rainfall deficiency. | V28: 111111 | X28: 123123 | AU28: 11 | AV28: 22 | AW28: 1 | AX28: 0 | AZ28: 1 | BA28: 2 | BB28: 3 | BE28: 112111 | BG28: 124123 | CB28: 1012 | CC28: 1013 | CD28: 1015 | CE28: 1016 | CF28: 1213 | CG28: 1215 | CH28: 1216 | CI28: 1315 | CJ28: 1316 | CK28: 1516 | EB28: 1 | ET28: =SUM(DO28:ES28) -> 1
A29: 13 | B29: Crop damage | C29: excess precipitation | D29: 38 | E29: Excess precipitation | F29: Crop damage (excess precipitation) | G29: 28 | H29: =(A29*1000)+D29 -> 13038 | I29: Slate Gray | J29: 205 | K29: 149 | L29: 117 | M29: 255 | N29: =G29&": ("&J29&", "&K29&", "&L29&", "&M29&", "&F29&": "&H29&")," -> 28: (205, 149, 117, 255, Crop damage (excess precipitation): 13038), | O29: =VLOOKUP(Australia!B29,Impacts!$A$2:$B$80,2, FALSE) -> Loss of or harm to crops during or following a disturbance. | P29: =VLOOKUP(E29,Pressures!$A$2:$B$145,2,FALSE) -> Above-normal increase in the amount of rain or snowfall. | V29: 111111 | X29: 123123 | AU29: 11 | AV29: 22 | AW29: 1 | AX29: 0 | AZ29: 1 | BA29: 2 | BB29: 3 | BE29: 112111 | BG29: 124123 | CB29: 1012 | CC29: 1013 | CD29: 1015 | CE29: 1016 | CF29: 1213 | CG29: 1215 | CH29: 1216 | CI29: 1315 | CJ29: 1316 | CK29: 1516 | EB29: 1 | ET29: =SUM(DO29:ES29) -> 1
A30: 13 | B30: Crop damage | C30: excess rain | D30: 39 | E30: Excess rain | F30: Crop damage (excess rain) | G30: 29 | H30: =(A30*1000)+D30 -> 13039 | I30: Lavender | J30: 145 | K30: 95 | L30: 109 | M30: 255 | N30: =G30&": ("&J30&", "&K30&", "&L30&", "&M30&", "&F30&": "&H30&")," -> 29: (145, 95, 109, 255, Crop damage (excess rain): 13039), | O30: =VLOOKUP(Australia!B30,Impacts!$A$2:$B$80,2, FALSE) -> Loss of or harm to crops during or following a disturbance. | P30: =VLOOKUP(E30,Pressures!$A$2:$B$145,2,FALSE) -> Heavy rainfall associated with the passage of a storm or tropical cyclone than can produce extensive flooding. | V30: 111111 | X30: 123123 | AU30: 11 | AV30: 22 | AW30: -1 | AX30: 0 | AZ30: 1 | BA30: 2 | BB30: 3 | BD30: 111112 | BF30: 123124 | CB30: 1012 | CC30: 1013 | CD30: 1015 | CE30: 1016 | CF30: 1213 | CG30: 1215 | CH30: 1216 | CI30: 1315 | CJ30: 1316 | CK30: 1516 | EB30: 1 | ET30: =SUM(DO30:ES30) -> 1
A31: 13 | B31: Crop damage | C31: flooding | D31: 44 | E31: Flooding | F31: Crop damage (flooding) | G31: 30 | H31: =(A31*1000)+D31 -> 13044 | I31: Ghost White | J31: 18 | K31: 97 | L31: 128 | M31: 255 | N31: =G31&": ("&J31&", "&K31&", "&L31&", "&M31&", "&F31&": "&H31&")," -> 30: (18, 97, 128, 255, Crop damage (flooding): 13044), | O31: =VLOOKUP(Australia!B31,Impacts!$A$2:$B$80,2, FALSE) -> Loss of or harm to crops during or following a disturbance. | P31: =VLOOKUP(E31,Pressures!$A$2:$B$145,2,FALSE) -> The inundation of water over land that is generally dry. | V31: 111111 | X31: 123123 | AU31: 11 | AV31: 22 | AW31: -1 | AX31: 0 | AZ31: 1 | BA31: 2 | BB31: 3 | BD31: 111111 | CB31: 1012 | CC31: 1013 | CD31: 1015 | CE31: 1016 | CF31: 1213 | CG31: 1215 | CH31: 1216 | CI31: 1315 | CJ31: 1316 | CK31: 1516 | DS31: 1 | ET31: =SUM(DO31:ES31) -> 1
A32: 13 | B32: Crop damage | C32: grazing (natural) | D32: 48 | E32: Grazing (natural) | F32: Crop damage (grazing (natural)) | G32: 31 | H32: =(A32*1000)+D32 -> 13048 | I32: Blue | J32: 244 | K32: 164 | L32: 96 | M32: 255 | N32: =G32&": ("&J32&", "&K32&", "&L32&", "&M32&", "&F32&": "&H32&")," -> 31: (244, 164, 96, 255, Crop damage (grazing (natural)): 13048), | O32: =VLOOKUP(Australia!B32,Impacts!$A$2:$B$80,2, FALSE) -> Loss of or harm to crops during or following a disturbance. | P32: =VLOOKUP(E32,Pressures!$A$2:$B$145,2,FALSE) -> Repetitive consumption of herbaceous or woody vegetation by herbivores/omnivores. | V32: 111111 | X32: 123123 | AU32: 11 | AV32: 22 | AW32: -1 | AX32: 0 | AZ32: 1 | BA32: 2 | BB32: 3 | BD32: 111111 | CB32: 1012 | CC32: 1013 | CD32: 1015 | CE32: 1016 | CF32: 1213 | CG32: 1215 | CH32: 1216 | CI32: 1315 | CJ32: 1316 | CK32: 1516 | EI32: 1 | ET32: =SUM(DO32:ES32) -> 1
A33: 13 | B33: Crop damage | C33: grazing (stock) | D33: 49 | E33: Grazing (stock) | F33: Crop damage (grazing (stock)) | G33: 32 | H33: =(A33*1000)+D33 -> 13049 | I33: Green | J33: 160 | K33: 82 | L33: 45 | M33: 255 | N33: =G33&": ("&J33&", "&K33&", "&L33&", "&M33&", "&F33&": "&H33&")," -> 32: (160, 82, 45, 255, Crop damage (grazing (stock)): 13049), | O33: =VLOOKUP(Australia!B33,Impacts!$A$2:$B$80,2, FALSE) -> Loss of or harm to crops during or following a disturbance. | P33: =VLOOKUP(E33,Pressures!$A$2:$B$145,2,FALSE) -> Repetitive consumption of herbaceous or woody vegetation by domesticated herbivores/omnivores. | V33: 111111 | X33: 123123 | AU33: 11 | AV33: 22 | AW33: -1 | AX33: 0 | AZ33: 1 | BA33: 2 | BB33: 3 | BE33: 111112 | CB33: 1012 | CC33: 1013 | CD33: 1015 | CE33: 1016 | CF33: 1213 | CG33: 1215 | CH33: 1216 | CI33: 1315 | CJ33: 1316 | CK33: 1516 | EJ33: 1 | ET33: =SUM(DO33:ES33) -> 1
A34: 13 | B34: Crop damage | C34: increased wind | D34: 66 | E34: Increased wind | F34: Crop damage (increased wind) | G34: 33 | H34: =(A34*1000)+D34 -> 13066 | I34: Cyan | J34: 184 | K34: 125 | L34: 73 | M34: 255 | N34: =G34&": ("&J34&", "&K34&", "&L34&", "&M34&", "&F34&": "&H34&")," -> 33: (184, 125, 73, 255, Crop damage (increased wind): 13066), | O34: =VLOOKUP(Australia!B34,Impacts!$A$2:$B$80,2, FALSE) -> Loss of or harm to crops during or following a disturbance. | P34: =VLOOKUP(E34,Pressures!$A$2:$B$145,2,FALSE) -> A higher velocity of air movement into an area associated with, for example, cyclones, hurricans, typhoons, tornados, thunderstorms, storms or ice storms. | V34: 111111 | X34: 123123 | AU34: 11 | AV34: 22 | AW34: -1 | AX34: 0 | AZ34: 1 | BA34: 2 | BB34: 3 | BD34: 111111 | CB34: 1012 | CC34: 1013 | CD34: 1015 | CE34: 1016 | CF34: 1213 | CG34: 1215 | CH34: 1216 | CI34: 1315 | CJ34: 1316 | CK34: 1516 | EC34: 1 | ET34: =SUM(DO34:ES34) -> 1
A35: 13 | B35: Crop damage | C35: insect herbivory | D35: 67 | E35: Insect herbivory | F35: Crop damage (insect herbivory) | G35: 34 | H35: =(A35*1000)+D35 -> 13067 | I35: Red | J35: 255 | K35: 218 | L35: 185 | M35: 255 | N35: =G35&": ("&J35&", "&K35&", "&L35&", "&M35&", "&F35&": "&H35&")," -> 34: (255, 218, 185, 255, Crop damage (insect herbivory): 13067), | O35: =VLOOKUP(Australia!B35,Impacts!$A$2:$B$80,2, FALSE) -> Loss of or harm to crops during or following a disturbance. | P35: =VLOOKUP(E35,Pressures!$A$2:$B$145,2,FALSE) -> Increased presence of plant-consuming insects in an area. | V35: 111111 | X35: 123123 | AU35: 11 | AV35: 22 | AW35: 1 | AX35: 0 | AZ35: 1 | BA35: 2 | BB35: 3 | BL35: 210216 | CB35: 1012 | CC35: 1013 | CD35: 1015 | CE35: 1016 | CF35: 1213 | CG35: 1215 | CH35: 1216 | CI35: 1315 | CJ35: 1316 | CK35: 1516 | EI35: 1 | EO35: 1 | ET35: =SUM(DO35:ES35) -> 2
A36: 13 | B36: Crop damage | C36: strong winds | D36: 120 | E36: Strong winds | F36: Crop damage (strong winds) | G36: 35 | H36: =(A36*1000)+D36 -> 13120 | I36: Magenta | J36: 184 | K36: 115 | L36: 51 | M36: 255 | N36: =G36&": ("&J36&", "&K36&", "&L36&", "&M36&", "&F36&": "&H36&")," -> 35: (184, 115, 51, 255, Crop damage (strong winds): 13120), | O36: =VLOOKUP(Australia!B36,Impacts!$A$2:$B$80,2, FALSE) -> Loss of or harm to crops during or following a disturbance. | P36: =VLOOKUP(E36,Pressures!$A$2:$B$145,2,FALSE) -> A prolonged period of average wind speeds exceeding 40km/h during the day. | V36: 111111 | X36: 123123 | AU36: 11 | AV36: 22 | AW36: 0 | AX36: 0 | AZ36: 1 | BA36: 2 | BB36: 3 | BD36: 111111 | CB36: 1012 | CC36: 1013 | CD36: 1015 | CE36: 1016 | CF36: 1213 | CG36: 1215 | CH36: 1216 | CI36: 1315 | CJ36: 1316 | CK36: 1516 | EC36: 1 | ED36: 1 | ET36: =SUM(DO36:ES36) -> 2
A37: 14 | B37: Crop establishment | C37: planting | D37: 90 | E37: Planting | F37: Crop establishment (planting) | G37: 36 | H37: =(A37*1000)+D37 -> 14090 | I37: Yellow | J37: 167 | K37: 252 | L37: 0 | M37: 255 | N37: =G37&": ("&J37&", "&K37&", "&L37&", "&M37&", "&F37&": "&H37&")," -> 36: (167, 252, 0, 255, Crop establishment (planting): 14090), | O37: =VLOOKUP(Australia!B37,Impacts!$A$2:$B$80,2, FALSE) -> Planting of crops in an area on ploughed land. | P37: =VLOOKUP(E37,Pressures!$A$2:$B$145,2,FALSE) -> Placement of seeds, seedlings or saplings into the ground so they can grow, leading to an increase in vegetation amount or a change in plant species composition. | V37: 111111 | X37: 123123 | AU37: 1 | AV37: 2 | AW37: 0 | AX37: 0 | AZ37: 1 | BA37: 2 | BB37: 3 | BE37: 112216 | CB37: 1615 | CC37: 1613 | CD37: 1612 | CE37: 1610 | CF37: 1513 | CG37: 1512 | CH37: 1510 | CI37: 1312 | CJ37: 1310 | EM37: 1 | ET37: =SUM(DO37:ES37) -> 1
A38: 15 | B38: Cropland gain | C38: agricultural expansion | D38: 3 | E38: Agricultural expansion | F38: Cropland gain (agricultural expansion) | G38: 37 | H38: =(A38*1000)+D38 -> 15003 | I38: White | J38: 255 | K38: 240 | L38: 0 | M38: 255 | N38: =G38&": ("&J38&", "&K38&", "&L38&", "&M38&", "&F38&": "&H38&")," -> 37: (255, 240, 0, 255, Cropland gain (agricultural expansion): 15003), | O38: =VLOOKUP(Australia!B38,Impacts!$A$2:$B$80,2, FALSE) -> Increase of total cropping area or total area sown. | P38: =VLOOKUP(E38,Pressures!$A$2:$B$145,2,FALSE) -> Increase in area of arable lands and pasture used for food production. | AE38: 112111 | AF38: 112123 | AG38: 124111 | AH38: 124123 | AU38: 1 | AV38: 2 | AW38: 0 | AX38: 0 | AZ38: 1 | BA38: 2 | BB38: 3 | BI38: 216216 | BZ38: 12 | CA38: 21 | EM38: 1 | ET38: =SUM(DO38:ES38) -> 1
A39: 15 | B39: Cropland gain | C39: farmland creation | D39: 42 | E39: Farmland creation | F39: Cropland gain (farmland creation) | G39: 38 | H39: =(A39*1000)+D39 -> 15042 | I39: Alice Blue | J39: 255 | K39: 182 | L39: 30 | M39: 255 | N39: =G39&": ("&J39&", "&K39&", "&L39&", "&M39&", "&F39&": "&H39&")," -> 38: (255, 182, 30, 255, Cropland gain (farmland creation): 15042), | O39: =VLOOKUP(Australia!B39,Impacts!$A$2:$B$80,2, FALSE) -> Increase of total cropping area or total area sown. | P39: =VLOOKUP(E39,Pressures!$A$2:$B$145,2,FALSE) -> Conversion of land to commercial, subsistence, intensive or extensive farming. | AE39: 112111 | AF39: 112123 | AG39: 124111 | AH39: 124123 | AU39: 1 | AV39: 2 | AW39: 0 | AX39: 0 | AZ39: 1 | BA39: 2 | BB39: 3 | BD39: 111111 | BE39: 112112 | BF39: 123123 | BG39: 124124 | BH39: 215215 | BI39: 216216 | BJ39: 227227 | BK39: 228228 | BL39: 220220 | BZ39: 12 | CA39: 21 | EM39: 1 | ET39: =SUM(DO39:ES39) -> 1
A40: 16 | B40: Cropland loss | C40: agricultural loss | D40: 4 | E40: Agricultural loss | F40: Cropland loss (agricultural loss) | G40: 39 | H40: =(A40*1000)+D40 -> 16004 | I40: Antique White | J40: 123 | K40: 63 | L40: 0 | M40: 255 | N40: =G40&": ("&J40&", "&K40&", "&L40&", "&M40&", "&F40&": "&H40&")," -> 39: (123, 63, 0, 255, Cropland loss (agricultural loss): 16004), | O40: =VLOOKUP(Australia!B40,Impacts!$A$2:$B$80,2, FALSE) -> Decrease of total cropping area or total area sown. | P40: =VLOOKUP(E40,Pressures!$A$2:$B$145,2,FALSE) -> Decrease in area of arable lands and pasture used for food production. | AE40: 111112 | AF40: 111124 | AG40: 123112 | AH40: 123124 | AW40: -1 | AX40: 0 | AZ40: 1 | BA40: 2 | BB40: 3 | BD40: 111111 | BE40: 112112 | BF40: 123123 | BG40: 124124 | BH40: 215215 | BI40: 216216 | BJ40: 227227 | BK40: 228228 | BL40: 220220 | EM40: 1 | ET40: =SUM(DO40:ES40) -> 1
...

Sheet colours
A1: ID_Colour | B1: R | C1: G | D1: B | E1: Colour | F1: A | G1: Code
A2: Medium Slate Blue | B2: 123 | C2: 104 | D2: 238 | F2: 255 | G2: 1113: (123, 104, 238, 255, Accretion (sediment transport)),
A3: Light Slate Gray | B3: 119 | C3: 136 | D3: 153 | F3: 255 | G3: 2038: (119, 136, 153, 255, Algal bloom (eutrophication)),
A4: Medium Orchid | B4: 186 | C4: 85 | D4: 211 | F4: 255 | G4: 2060: (186, 85, 211, 255, Algal bloom (high inland water temperatures)),
A5: Light Salmon | B5: 255 | C5: 160 | D5: 122 | F5: 255 | G5: 2068: (255, 160, 122, 255, Algal bloom (increased temperature)),
A6: Dark Turquoise | B6: 0 | C6: 206 | D6: 209 | F6: 255 | G6: 3027: (0, 206, 209, 255, Algal dieback (decreased temperature)),
A7: Light Sky Blue | B7: 135 | C7: 206 | D7: 250 | F7: 255 | G7: 4012: (135, 206, 250, 255, Bare soil exposure (burning)),
A8: Light Steel Blue | B8: 176 | C8: 196 | D8: 222 | F8: 255 | G8: 4037: (176, 196, 222, 255, Bare soil exposure (erosion)),
A9: Medium Purple | B9: 147 | C9: 112 | D9: 219 | F9: 255 | G9: 4093: (147, 112, 219, 255, Bare soil exposure (ploughing)),
A10: Pale Violet Red | B10: 219 | C10: 112 | D10: 147 | F10: 255 | G10: 4127: (219, 112, 147, 255, Bare soil exposure (tillage)),
A11: Light Green | B11: 144 | C11: 238 | D11: 144 | F11: 255 | G11: 5072: (144, 238, 144, 255, Blackwater event (inundation following extended drought)),
A12: Medium Spring Green | B12: 0 | C12: 250 | D12: 154 | F12: 255 | G12: 6026: (0, 250, 154, 255, Browning (vegetation) (decreased precipitation)),
A13: Light Cyan | B13: 224 | C13: 255 | D13: 255 | F13: 255 | G13: 7022: (224, 255, 255, 255, Building or infrastructure abandonment (dam removal)),
... A247: Pear | B247: 209 | C247: 226 | D247: 49 | F247: 255 | G247: 75094: (209, 226, 49, 255, Water quality change (pollution)),
A248: Teal Blue | B248: 54 | C248: 117 | D248: 136 | G248: : (54, 117, 136, , ),
A249: Neon Green | B249: 57 | C249: 255 | D249: 20 | G249: : (57, 255, 20, , ),
A250: Neon Fuchsia | B250: 254 | C250: 65 | D250: 100 | G250: : (254, 65, 100, , ),
A251: Dark Brown | B251: 101 | C251: 67 | D251: 33 | G251: : (101, 67, 33, , ),
A252: Khaki Web | B252: 195 | C252: 176 | D252: 145 | G252: : (195, 176, 145, , ),
A253: Iceberg | B253: 113 | C253: 166 | D253: 210 | G253: : (113, 166, 210, , ),
A254: Jasmine | B254: 248 | C254: 222 | D254: 126 | G254: : (248, 222, 126, , ),
A255: Mahogany | B255: 192 | C255: 64 | D255: 0 | G255: : (192, 64, 0, , ),
A256: French Rose | B256: 246 | C256: 74 | D256: 138 | G256: : (246, 74, 138, , ),
A257: Cyan-Blue Azure | B257: 70 | C257: 130 | D257: 191 | G257: : (70, 130, 191, , ),
A258: Fuchsia | B258: 255 | C258: 0 | D258: 255 | G258: : (255, 0, 255, , ),

Sheet Impacts
A1: Term | B1: Definition short | C1: Definition | E1: Copyright | F1: Authority | G1: Authority citation | H1: Authority link
A2: Accretion | B2: The build-up of sediments to form land or shoaling in coastal waters or waterways. | C2: The build-up of sediments to form land or shoaling in coastal waters or waterways. It may be either natural or artificial. Natural accretion is the build-up of land on the beach, dunes, or in the water by natural processes, such as waves, current and wind. Artificial accretion is a similar build-up of land resulting from built structures such as groynes or breakwaters, or activities such as filling and beach nourishment, or also aggradation. | E2: The definition for this term is re-used from 'Costal Management Glossary', Office of Environment and Heritage © 2018 State of NSW and Office of Environment and Heritage. It is licensed under the Creative Commons Attribution 4.0 International (CC BY 4.0). | F2: Office of Environment and Heritage | G2: OEH 2018. Coastal Management Glossary. <last accessed 14th Dec 2020 https://www.environment.nsw.gov.au/research-and-publications/publications-search/coastal-management-glossary> | H2: https://www.environment.nsw.gov.au/-/media/OEH/Corporate-Site/Documents/Water/Coasts/coastal-management-glossary-180195.pdf
A3: Algal bloom | B3: A sudden proliferation of algae (microscopic plants) that occurs near the surface of a body of water. | C3: A sudden proliferation of algae (microscopic plants) that occurs near the surface of a body of water. Blooms can occur due to natural nutrient cycles, or can be in response to eutrophication or climate variations. | E3: The definition for this term is re-used from Australia State of the Environment 2016 Glossary, © Commonwealth of Australia 2017-2018. It is licenced by the Commonwealth of Australia for use under a Creative Commons Attribution 4.0 International licence. | F3: Australia State of the Environment 2016 | G3: - | H3: https://soe.environment.gov.au/glossary
A4: Algal dieback | B4: Loss of algae (microscopic plants) that occurs near the surface of a body of water. | C4: Loss of algae (microscopic plants) that occurs near the surface of a body of water. | E4: Part of the definition for this term is re-used from Australia State of the Environment 2016 Glossary, © Commonwealth of Australia 2017-2018. It is licenced by the Commonwealth of Australia for use under a Creative Commons Attribution 4.0 International licence. | F4: Australia State of the Environment 2016 | G4: - | H4: https://soe.environment.gov.au/glossary
A5: Bare soil exposure | B5: Appearance of underlying soil following human or natural disturbance.. | C5: Appearance of underlying soil following human or natural disturbance, such as removal of top soil prior to urban construction or grazing of natural vegetation. | E5: Creative Commons Attribution 4.0 International (CC BY 4.0) license, on any reports made public under this Project Agreement. | F5: Land Ecosystem Accounts Project | G5: - | H5: General - no source
A6: Blackwater event | B6: When organic material is inundated or washed into waterways and consumed by bacteria. | C6: When organic material is inundated or washed into waterways and consumed by bacteria, leading to a sudden depletion of dissolved oxygen in the water. | E6: The definition for this term is re-used from Australia State of the Environment 2016 Glossary, © Commonwealth of Australia 2017-2018. It is licenced by the Commonwealth of Australia for use under a Creative Commons Attribution 4.0 International licence. | F6: Australia State of the Environment 2016 | G6: - | H6: https://soe.environment.gov.au/glossary
A7: Browning (vegetation) | B7: A decrease in the amount or loss of photosynthetically active pigments in vegetation. | C7: A decrease in the amount or loss of photosynthetically active pigments (primarily chlorophylls) in vegetation. | E7: Creative Commons Attribution 4.0 International (CC BY 4.0) license, on any reports made public under this Project Agreement. | F7: Land Ecosystem Accounts Project | G7: - | H7: General - no source
A8: Building or infrastucture abandonment | B8: Buildings dehabited or no longer in use. | C8: Buildings dehabited or no longer in use. | E8: Creative Commons Attribution 4.0 International (CC BY 4.0) license, on any reports made public under this Project Agreement. | F8: Land Ecosystem Accounts Project | G8: - | H8: General - no source
A9: Compaction | B9: Process that brings about an increase in soil density or unit weight. | C9: Process that brings about an increase in soil density or unit weight, accompanied by a decrease in air volume. | E9: The definition for this term is re-used from 'Compaction', University of West England, Copyright 2020 © UWE Bristol | F9: University of New England | G9: - | H9: http://environment.uwe.ac.uk/geocal/SoilMech/compaction/compaction.htm
A10: Coral bleaching | B10: When the coral host expels its zooxanthellae. | C10: When the coral host expels its zooxanthellae (marine algae living in symbiosis with the coral) in response to increased water temperatures, often resulting in the death of the coral. | E10: Part of the definition for this term is re-used from Australia State of the Environment 2016 Glossary, © Commonwealth of Australia 2017-2018. It is licenced by the Commonwealth of Australia for use under a Creative Commons Attribution 4.0 International licence. | F10: Australia State of the Environment 2016 | G10: - | H10: https://soe.environment.gov.au/glossary
A11: Coral damage | B11: Physical damage or loss of a coral reef not caused b y changes in water temperature | C11: Physical damage or loss of a coral reef that is not the result of changes in water. temperature. | E11: Creative Commons Attribution 4.0 International (CC BY 4.0) license, on any reports made public under this Project Agreement. | F11: Land Ecosystem Accounts Project | G11: - | H11: General - no source
A12: Coral recovery | B12: Re-instatement of the previous extent or health of reef-building corals. | C12: Re-instatement of the previous extent or health of reef-building corals. | E12: Creative Commons Attribution 4.0 International (CC BY 4.0) license, on any reports made public under this Project Agreement. | F12: Land Ecosystem Accounts Project | G12: - | H12: General - no source
... A19: Desalinisation | B19: The process of soils becoming less salty. | C19: The process of soils becoming less salty; the reduction of soluble salts in water bodies. | E19: Part of the definition for this term is re-used from Australia State of the Environment 2016 Glossary, © Commonwealth of Australia 2017-2018. It is licenced by the Commonwealth of Australia for use under a Creative Commons Attribution 4.0 International licence. | F19: Australia State of the Environment 2016 | G19: - | H19: https://soe.environment.gov.au/glossary
A20: Desertification | B20: Reduction in the productivity of the land that is not reversible. | C20: Reduction in the productivity of the land that is not reversible. In other words, land is desertified when it can no longer support the same plant growth it had in the past, and the change is permanent on a human time scale. | E20: Part of the definition for this term is re-used from 'Defining Desertification', NASA Earth Observatory. No specific copyright info (only this: https://www.nasa.gov/multimedia/guidelines/index.html) | F20: NASA Earth Observatory | H20: https://earthobservatory.nasa.gov/features/Desertification/desertification2.php
A21: Elevation change | B21: Change in the altitude above sea or ground level. | C21: Change in the altitude above sea or ground level. | E21: Part of the definition for this term is re-used from 'Elevation', Macquarie Dictionary. © Macmillan Publishers Australia 2020. All rights reserved. | F21: Macquarie Dictionary | G21: - | H21: https://www.macquariedictionary.com.au/features/word/search/?search_word_type=Dictionary&word=elevation
A22: Erosion | B22: Geological process in which earthen materials are worn away and transported by natural forces. | C22: Geological process in which earthen materials are worn away and transported by natural forces such as wind or water. | E22: The definition for this term is re-used from 'Erosion', National Geographic. © 1996 - 2020 National Geographic Society. All rights reserved. | F22: National Geographic | G22: - | H22: https://www.nationalgeographic.org/encyclopedia/erosion/#:~:text=Erosion%20is%20the%20geological%20process,such%20as%20wind%20or%20water.
A23: Flooding | B23: Inundation of water over an area. | C23: Inundation of water over an area. | E23: Creative Commons Attribution 4.0 International (CC BY 4.0) license, on any reports made public under this Project Agreement. | F23: Land Ecosystem Accounts Project | G23: - | H23: General - no source
A24: Geomorphological change | B24: A geomorphic adjustment that changes the geometry of landforms. | C24: A geomorphic adjustment that changes the geometry of landforms. Examples include estuarine evolution and beach rotation in coastal areas and mountain uplift. | E24: Creative Commons Attribution 4.0 International (CC BY 4.0) license, on any reports made public under this Project Agreement. | F24: Land Ecosystem Accounts Project | G24: - | H24: General - no source
A25: Glaciation | B25: Expansion of ice or glacier cover. | C25: Expansion of ice or glacier cover. | E25: Creative Commons Attribution 4.0 International (CC BY 4.0) license, on any reports made public under this Project Agreement. | F25: Land Ecosystem Accounts Project | G25: - | H25: General - no source
A26: Greening | B26: An increase in the amount of photosynthetically active pigments in vegetation. | C26: An increase in the amount of photosynthetically active pigments (primarily chlorophylls) in vegetation. | E26: Creative Commons Attribution 4.0 International (CC BY 4.0) license, on any reports made public under this Project Agreement. | F26: Land Ecosystem Accounts Project | G26: - | H26: General - no source
A27: Increased sediment load | B27: Increase in the amount of a substance discharged into a body of water. | C27: Increase in the amount of a substance discharged into a body of water (e.g. salt or sediment). | E27: Part of the definition for this term is re-used from 'Glossary', Northern Territory Environment Protection Authority,© Copyright 2020 NTEPA | F27: Northern Territory Environment Protection Authority | G27: NTEPA 2005, Glossary, Enesar Consulting Pty Ltd, NTEPA | H27: https://ntepa.nt.gov.au/__data/assets/pdf_file/0007/286567/chp12.pdf
A28: Inundation | B28: Progressive submergence of land or structures through flooding. | C28: Progressive submergence of land or structures through flooding. | E28: Creative Commons Attribution 4.0 International (CC BY 4.0) license, on any reports made public under this Project Agreement. | F28: New South Wales State Emergency Service | G28: SES 2018, New South Wales State Flood Plan Glossary, Page 3, [https://www.ses.nsw.gov.au/about-us/flood-storm-and-tsunami-plans/][last accessed 10th Dec 2020] | H28: https://www.ses.nsw.gov.au/media/2650/glossary.pdf
A29: Invasive or exotic species | B29: A plant or animal that has been introduced into a region (terrestrial or aquatic). | C29: A plant or animal that has been introduced into a region (terrestrial or aquatic) in which it does not naturally occur and that becomes established and spreads, displacing naturally occurring species. | E29: Creative Commons Attribution 4.0 International (CC BY 4.0) license, on any reports made public under this Project Agreement. | F29: Land Ecosystem Accounts Project | G29: - | H29: General - no source
A30: Lava flow | B30: A mass of molten rock produced during the eruption of a volcano and moving down its sides. | C30: A mass of molten rock produced during the eruption of a volcano and moving down its sides. | E30: The definition for this term is re-used from 'Lava flow', Macquarie Dictionary. © Macmillan Publishers Australia 2020. All rights reserved. | F30: Macquarie Dictionary | G30: - | H30: https://www.macquariedictionary.com.au/features/word/search/?search_word_type=Dictionary&word=lava+flow
A31: Leaf scorch | B31: A non-infectious, physiological condition caused by unfavorable environmental situations. | C31: A non-infectious, physiological condition caused by unfavorable environmental situations. It is not caused by fungus, bacteria, or virus. The problem may appear on almost any plant if weather conditions are favourable, such as high temperatures, dry winds, salt carrying winds and low soil moisture. | E31: The definition for this term is re-used from 'Leaf scorch', The Morton Arboretum, © 2021 The Morton Arboretum | F31: The Morton Arboretum | G31: - | H31: https://mortonarb.org/plant-and-protect/tree-plant-care/plant-care-resources/leaf-scorch/#!
A32: Mine abandonment | B32: Land formally used for extractive industry but no longer in use and no new use observed. | C32: Land formally used for extractive industry but no longer in use and no new use observed. | E32: Creative Commons Attribution 4.0 International (CC BY 4.0) license, on any reports made public under this Project Agreement. | F32: Land Ecosystem Accounts Project | G32: - | H32: General - no source
... A52: Sedimentation | B52: Deposition of sediment from flowing or standing water | C52: Deposition of sediment from flowing water (in channels or floodplains) or standing water (in wetlands, lakes, or oceans). | E52: The definition for this term is re-used from ' Soil erosion: the greatest challenge to sustainable soil management', Food and Agriculture Organisation; © FAO, 2019. Some rights reserved. This work is made available under the Creative Commons AttributionNonCommercial-ShareAlike 3.0 IGO licence | F52: Food and Agriculture Organisation of the United Nations | G52: FAO. 2019. Soil erosion: the greatest challenge to sustainable soil management. Rome. 100 pp. Licence: CC BY-NC-SA 3.0 IGO. http://www.fao.org/3/ca4395en/ca4395en.pdf | H52: http://www.fao.org/3/ca4395en/ca4395en.pdf
A53: Sinkhole | B53: A closed natural depression in the ground surface. | C53: A sinkhole is a closed natural depression in the ground surface caused by removal of material below the ground and either collapse or gradual subsidence of the surface into the resulting void. | E53: The definition for this term is re-used from 'What is the difference between a sinkhole and a pothole?', USGS. Generally, materials produced by federal agencies are in the public domain and may be reproduced without permission. | F53: United States Geological Survey | H53: https://www.usgs.gov/faqs/what-difference-between-a-sinkhole-and-a-pothole?qt-news_science_products=0#qt-news_science_products
A54: Snow accumulation | B54: Gradual gathering of snow over an area already covered in snow. | C54: Gradual gathering of snow over an area already covered in snow. | E54: Creative Commons Attribution 4.0 International (CC BY 4.0) license, on any reports made public under this Project Agreement. | F54: Land Ecosystem Accounts Project | G54: - | H54: General - no source
A55: Snow melt | B55: Loss of snow cover due to heat. | C55: Loss of snow cover due to heat. | E55: Creative Commons Attribution 4.0 International (CC BY 4.0) license, on any reports made public under this Project Agreement. | F55: Land Ecosystem Accounts Project | G55: - | H55: General - no source
A56: Urban damage | B56: Damage to urban buildings and infrastructure. | C56: Damage to urban buildings and infrastructure. | E56: Creative Commons Attribution 4.0 International (CC BY 4.0) license, on any reports made public under this Project Agreement. | F56: Land Ecosystem Accounts Project | G56: - | H56: General - no source
A57: Urban decay | B57: The process of deterioration in the integrity of buildings and infrastructure. | C57: The process of deterioration in the integrity of buildings and infrastructure. | E57: Part of the definition for this term is re-used from 'Dictionary of Geographical Terms', © 2007 - 2020 Collins Learning, a division of HarperCollins Publishers Ltd, registered in Scotland, Company No.27389. Registered address: Westerhill Road, Bishopbriggs, Glasgow, G64 2QT. © 2020 National Geographic Partners, LLC. | F57: Collins Dictionary | G57: - | H57: https://resources.collins.co.uk/Wesbite%20images/KS3Geography/TB2/Dictionary%20of%20geographical%20terms.pdf
A58: Urban densification | B58: Increases in the number of buildings and associated infrastructure. | C58: Increases in the number of buildings and associated infrastructure as human populations move into an area to live or work. | E58: Creative Commons Attribution 4.0 International (CC BY 4.0) license, on any reports made public under this Project Agreement. | F58: Land Ecosystem Accounts Project | G58: - | H58: General - no source
A59: Urban development | B59: Economic, social and political changes that improve the wellbeing of people in an urban setting. | C59: Economic, social and political changes that improve the wellbeing of people in an urban setting. | E59: Part of the definition for this term is re-used from 'Glossary', Australian Curriculum, © Australian Curriculum, Assessment and Reporting Authority. | F59: Australian Curriculum | G59: - | H59: https://www.australiancurriculum.edu.au/f-10-curriculum/humanities-and-social-sciences/geography/glossary/?letter=D
A60: Urban growth | B60: Increase urban area through the construction of buildings and associated infrastructure. | C60: Increase in extent of urban land cover through the construction of buildings and associated infrastructure. | E60: Creative Commons Attribution 4.0 International (CC BY 4.0) license, on any reports made public under this Project Agreement. | F60: Land Ecosystem Accounts Project | G60: - | H60: General - no source
A61: Urban area loss | B61: Removal of all settlements above a certain minimum population size and density. | C61: Removal of all settlements above a certain minimum population size and minimum population density that are within a certain travel time by road. | E61: Part of the definition for this term is re-used from © 2009 The International Bank for Reconstruction and Development/The World Bank | F61: World Bank World Development Report 2009 | G61: - | H61: http://www-wds.worldbank.org/external/default/WDSContentServer/WDSP/IB/2008/12/03/000333038_20081203234958/Rendered/PDF/437380REVISED01BLIC1097808213760720.pdf
A62: Urban renewal | B62: Redevelopment of a built environment to address urban decay. | C62: Redevelopment of a built environment to address urban decay. | E62: Creative Commons Attribution 4.0 International (CC BY 4.0) license, on any reports made public under this Project Agreement. | F62: Land Ecosystem Accounts Project | G62: - | H62: General - no source
A63: Urban sprawl | B63: Unplanned low-density development surrounding an urban area. | C63: Unplanned low-density development surrounding an urban area that often starts as rural land. Also called suburban sprawl. | E63: The definition for this term is re-used from 'Glossary', National Geographic. © 1996 - 2020 National Geographic Society. All rights reserved. | F63: National Geographic | G63: - | H63: https://www.nationalgeographic.org/glossary/?page=3&term=urban
A64: Vegetation damage | B64: Physical harm that impairs the value, usefulness, or normal function of plants or plant communities. | C64: Physical harm that impairs the value, usefulness, or normal function of plants or plant communities. | E64: Part of the definition for this term is re-used from 'Damage', Lexico, powered by Oxford © 2021 Lexico.com | F64: Lexico | G64: - | H64: https://www.lexico.com/definition/damage
A65: Vegetation dieback | B65: Mortality of all or part of plant components, either sinularly or en masse. | C65: Mortality of all or part of plant components, either sinularly or en masse. | E65: Creative Commons Attribution 4.0 International (CC BY 4.0) license, on any reports made public under this Project Agreement. | F65: Land Ecosystem Accounts Project | G65: - | H65: General - no source
...

Sheet Pressures
A1: Pressure | B1: Definition short | C1: Definition | D1: Copyright | E1: Authority | F1: Authority citation
